Workbook

Sheet Delete All
A1: ALTER TABLE Phases NOCHECK CONSTRAINT ALL
A2: ALTER TABLE Strategies NOCHECK CONSTRAINT ALL
A3: ALTER TABLE PhaseStrategies NOCHECK CONSTRAINT ALL
A4: ALTER TABLE Channels NOCHECK CONSTRAINT ALL
A5: ALTER TABLE PSChannels NOCHECK CONSTRAINT ALL
A6: ALTER TABLE Countries NOCHECK CONSTRAINT ALL
A7: ALTER TABLE PSChannelCountries NOCHECK CONSTRAINT ALL
A8: ALTER TABLE Ads NOCHECK CONSTRAINT ALL
A9: ALTER TABLE PSChannelCountryAds NOCHECK CONSTRAINT ALL
A10: DELETE FROM Phases;
A11: DELETE FROM Strategies;
A12: DELETE FROM PhaseStrategies;
... A18: DELETE FROM PSChannelCountryAds;

Sheet All Inserts
A1: EXEC sp_msforeachtable "ALTER TABLE ? NOCHECK CONSTRAINT all"
A2: SET IDENTITY_INSERT Phases OFF;
A3: SET IDENTITY_INSERT Strategies OFF;
A4: SET IDENTITY_INSERT Channels OFF;
A5: SET IDENTITY_INSERT Countries OFF;
A6: SET IDENTITY_INSERT Ads OFF;
A8: =Phases!K8 -> ALTER TABLE Phases NOCHECK CONSTRAINT ALL
A9: =Phases!K9 -> DELETE FROM Phases;
A10: =Phases!K10 -> SET IDENTITY_INSERT Phases ON;
A11: =Phases!K11 -> INSERT INTO Phases(Id, Name, StartDate, EndDate) VALUES (1,'Phase 1','20200101','20200331');
A12: =Phases!K12 -> INSERT INTO Phases(Id, Name, StartDate, EndDate) VALUES (2,'Phase 2','20200401','20200630');
A13: =Phases!K13 -> INSERT INTO Phases(Id, Name, StartDate, EndDate) VALUES (3,'Phase 3','20200701','20200930');
A14: =Phases!K14 -> INSERT INTO Phases(Id, Name, StartDate, EndDate) VALUES (4,'Phase 4','20201001','20201231');
A15: =Phases!K15 -> ALTER TABLE Phases WITH CHECK CHECK CONSTRAINT ALL
A16: =Phases!K16 -> SET IDENTITY_INSERT Phases OFF;
A18: =Strategies!K8 -> ALTER TABLE Strategies NOCHECK CONSTRAINT ALL
A19: =Strategies!K9 -> DELETE FROM Strategies;
A20: =Strategies!K10 -> SET IDENTITY_INSERT Strategies ON;
A21: =Strategies!K11 -> INSERT INTO Strategies(Id, Name, StartDate, EndDate) VALUES (1,'Strategy 1','20200101','20200331');
A22: =Strategies!K12 -> INSERT INTO Strategies(Id, Name, StartDate, EndDate) VALUES (2,'Strategy 2','20200401','20200630');
A23: =Strategies!K13 -> INSERT INTO Strategies(Id, Name, StartDate, EndDate) VALUES (3,'Strategy 3','20200701','20200930');
A24: =Strategies!K14 -> INSERT INTO Strategies(Id, Name, StartDate, EndDate) VALUES (4,'Strategy 4','20201001','20201231');
A25: =Strategies!K15 -> ALTER TABLE Strategies WITH CHECK CHECK CONSTRAINT ALL
A26: =Strategies!K16 -> SET IDENTITY_INSERT Strategies OFF;
A28: =PhaseStrategies!I8 -> ALTER TABLE PhaseStrategies NOCHECK CONSTRAINT ALL
A29: =PhaseStrategies!I9 -> DELETE FROM PhaseStrategies;
A30: =PhaseStrategies!I10 -> SET IDENTITY_INSERT PhaseStrategies ON;
A31: =PhaseStrategies!I11 -> INSERT INTO PhaseStrategies(Id, PhaseId, StrategyId) VALUES (1,1,1);
A32: =PhaseStrategies!I12 -> INSERT INTO PhaseStrategies(Id, PhaseId, StrategyId) VALUES (2,2,2);
A33: =PhaseStrategies!I13 -> INSERT INTO PhaseStrategies(Id, PhaseId, StrategyId) VALUES (3,3,3);
A34: =PhaseStrategies!I14 -> INSERT INTO PhaseStrategies(Id, PhaseId, StrategyId) VALUES (4,4,4);
A35: =PhaseStrategies!I15 -> ALTER TABLE PhaseStrategies WITH CHECK CHECK CONSTRAINT ALL
A36: =PhaseStrategies!I16 -> SET IDENTITY_INSERT PhaseStrategies OFF;
A38: =Channel!G8 -> ALTER TABLE Channels NOCHECK CONSTRAINT ALL
A39: =Channel!G9 -> DELETE FROM Channels;
A40: =Channel!G10 -> SET IDENTITY_INSERT Channels ON;
A41: =Channel!G11 -> INSERT INTO Channels(Id, Name) VALUES (1,'Programmatic');
A42: =Channel!G12 -> INSERT INTO Channels(Id, Name) VALUES (2,'YouTube');
A43: =Channel!G13 -> INSERT INTO Channels(Id, Name) VALUES (3,'Facebook / Instagram');
A44: =Channel!G14 -> INSERT INTO Channels(Id, Name) VALUES (4,'Instagram');
...

Sheet Phases
A1: Table Name | B1: Phases
A2: Start | B2: ="INSERT INTO " & B1 & "(" -> INSERT INTO Phases(
A3: Middle | B3: =") VALUES (" -> ) VALUES (
A4: End | B4: =");" -> );
A5: Columns | B5: =B10 -> Id | C5: =C10 -> Name | D5: =D10 -> StartDate | E5: =E10 -> EndDate
A6: All Columns | B6: =B5 -> Id | C6: =B6 & ", " & C5 -> Id, Name | D6: =C6 & ", " & D5 -> Id, Name, StartDate | E6: =D6 & ", " & E5 -> Id, Name, StartDate, EndDate
A7: Statement | B7: =B2 & E6 & B3 -> INSERT INTO Phases(Id, Name, StartDate, EndDate) VALUES (
K8: ="ALTER TABLE " & $B$1 & " NOCHECK CONSTRAINT ALL" -> ALTER TABLE Phases NOCHECK CONSTRAINT ALL
B9: Table Data | K9: ="DELETE FROM " & $B$1 & ";" -> DELETE FROM Phases;
B10: Id | C10: Name | D10: StartDate | E10: EndDate | K10: ="SET IDENTITY_INSERT " & $B$1 & " ON;" -> SET IDENTITY_INSERT Phases ON;
B11: 1 | C11: Phase 1 | D11: 43831 | E11: 43921 | F11: =B11 -> 1 | G11: ="'" & C11 & "'" -> 'Phase 1' | H11: ="'" & TEXT(D11, "YYYYMMDD") & "'" -> '20200101' | I11: ="'" & TEXT(E11, "YYYYMMDD") & "'" -> '20200331' | J11: =_xlfn.CONCAT(F11,",",G11,",",H11,",",I11) -> 1,'Phase 1','20200101','20200331' | K11: =$B$7 & J11 & $B$4 -> INSERT INTO Phases(Id, Name, StartDate, EndDate) VALUES (1,'Phase 1','20200101','20200331');
B12: 2 | C12: Phase 2 | D12: 43922 | E12: 44012 | F12: =B12 -> 2 | G12: ="'" & C12 & "'" -> 'Phase 2' | H12: ="'" & TEXT(D12, "YYYYMMDD") & "'" -> '20200401' | I12: ="'" & TEXT(E12, "YYYYMMDD") & "'" -> '20200630' | J12: =_xlfn.CONCAT(F12,",",G12,",",H12,",",I12) -> 2,'Phase 2','20200401','20200630' | K12: =$B$7 & J12 & $B$4 -> INSERT INTO Phases(Id, Name, StartDate, EndDate) VALUES (2,'Phase 2','20200401','20200630');
B13: 3 | C13: Phase 3 | D13: 44013 | E13: 44104 | F13: =B13 -> 3 | G13: ="'" & C13 & "'" -> 'Phase 3' | H13: ="'" & TEXT(D13, "YYYYMMDD") & "'" -> '20200701' | I13: ="'" & TEXT(E13, "YYYYMMDD") & "'" -> '20200930' | J13: =_xlfn.CONCAT(F13,",",G13,",",H13,",",I13) -> 3,'Phase 3','20200701','20200930' | K13: =$B$7 & J13 & $B$4 -> INSERT INTO Phases(Id, Name, StartDate, EndDate) VALUES (3,'Phase 3','20200701','20200930');
B14: 4 | C14: Phase 4 | D14: 44105 | E14: 44196 | F14: =B14 -> 4 | G14: ="'" & C14 & "'" -> 'Phase 4' | H14: ="'" & TEXT(D14, "YYYYMMDD") & "'" -> '20201001' | I14: ="'" & TEXT(E14, "YYYYMMDD") & "'" -> '20201231' | J14: =_xlfn.CONCAT(F14,",",G14,",",H14,",",I14) -> 4,'Phase 4','20201001','20201231' | K14: =$B$7 & J14 & $B$4 -> INSERT INTO Phases(Id, Name, StartDate, EndDate) VALUES (4,'Phase 4','20201001','20201231');
K15: ="ALTER TABLE " & $B$1 & " WITH CHECK CHECK CONSTRAINT ALL" -> ALTER TABLE Phases WITH CHECK CHECK CONSTRAINT ALL
K16: ="SET IDENTITY_INSERT " & $B$1 & " OFF;" -> SET IDENTITY_INSERT Phases OFF;

Sheet Strategies
A1: Table Name | B1: Strategies
A2: Start | B2: ="INSERT INTO " & B1 & "(" -> INSERT INTO Strategies(
A3: Middle | B3: =") VALUES (" -> ) VALUES (
A4: End | B4: =");" -> );
A5: Columns | B5: =B10 -> Id | C5: =C10 -> Name | D5: =D10 -> StartDate | E5: =E10 -> EndDate
A6: All Columns | B6: =B5 -> Id | C6: =B6 & ", " & C5 -> Id, Name | D6: =C6 & ", " & D5 -> Id, Name, StartDate | E6: =D6 & ", " & E5 -> Id, Name, StartDate, EndDate
A7: Statement | B7: =B2 & E6 & B3 -> INSERT INTO Strategies(Id, Name, StartDate, EndDate) VALUES (
K8: ="ALTER TABLE " & $B$1 & " NOCHECK CONSTRAINT ALL" -> ALTER TABLE Strategies NOCHECK CONSTRAINT ALL
B9: Table Data | K9: ="DELETE FROM " & $B$1 & ";" -> DELETE FROM Strategies;
B10: Id | C10: Name | D10: StartDate | E10: EndDate | K10: ="SET IDENTITY_INSERT " & $B$1 & " ON;" -> SET IDENTITY_INSERT Strategies ON;
B11: 1 | C11: Strategy 1 | D11: 43831 | E11: 43921 | F11: =B11 -> 1 | G11: ="'" & C11 & "'" -> 'Strategy 1' | H11: ="'" & TEXT(D11, "YYYYMMDD") & "'" -> '20200101' | I11: ="'" & TEXT(E11, "YYYYMMDD") & "'" -> '20200331' | J11: =_xlfn.CONCAT(F11,",",G11,",",H11,",",I11) -> 1,'Strategy 1','20200101','20200331' | K11: =$B$7 & J11 & $B$4 -> INSERT INTO Strategies(Id, Name, StartDate, EndDate) VALUES (1,'Strategy 1','20200101','20200331');
B12: 2 | C12: Strategy 2 | D12: 43922 | E12: 44012 | F12: =B12 -> 2 | G12: ="'" & C12 & "'" -> 'Strategy 2' | H12: ="'" & TEXT(D12, "YYYYMMDD") & "'" -> '20200401' | I12: ="'" & TEXT(E12, "YYYYMMDD") & "'" -> '20200630' | J12: =_xlfn.CONCAT(F12,",",G12,",",H12,",",I12) -> 2,'Strategy 2','20200401','20200630' | K12: =$B$7 & J12 & $B$4 -> INSERT INTO Strategies(Id, Name, StartDate, EndDate) VALUES (2,'Strategy 2','20200401','20200630');
B13: 3 | C13: Strategy 3 | D13: 44013 | E13: 44104 | F13: =B13 -> 3 | G13: ="'" & C13 & "'" -> 'Strategy 3' | H13: ="'" & TEXT(D13, "YYYYMMDD") & "'" -> '20200701' | I13: ="'" & TEXT(E13, "YYYYMMDD") & "'" -> '20200930' | J13: =_xlfn.CONCAT(F13,",",G13,",",H13,",",I13) -> 3,'Strategy 3','20200701','20200930' | K13: =$B$7 & J13 & $B$4 -> INSERT INTO Strategies(Id, Name, StartDate, EndDate) VALUES (3,'Strategy 3','20200701','20200930');
B14: 4 | C14: Strategy 4 | D14: 44105 | E14: 44196 | F14: =B14 -> 4 | G14: ="'" & C14 & "'" -> 'Strategy 4' | H14: ="'" & TEXT(D14, "YYYYMMDD") & "'" -> '20201001' | I14: ="'" & TEXT(E14, "YYYYMMDD") & "'" -> '20201231' | J14: =_xlfn.CONCAT(F14,",",G14,",",H14,",",I14) -> 4,'Strategy 4','20201001','20201231' | K14: =$B$7 & J14 & $B$4 -> INSERT INTO Strategies(Id, Name, StartDate, EndDate) VALUES (4,'Strategy 4','20201001','20201231');
K15: ="ALTER TABLE " & $B$1 & " WITH CHECK CHECK CONSTRAINT ALL" -> ALTER TABLE Strategies WITH CHECK CHECK CONSTRAINT ALL
K16: ="SET IDENTITY_INSERT " & $B$1 & " OFF;" -> SET IDENTITY_INSERT Strategies OFF;

Sheet PhaseStrategies
A1: Table Name | B1: PhaseStrategies
A2: Start | B2: ="INSERT INTO " & B1 & "(" -> INSERT INTO PhaseStrategies(
A3: Middle | B3: =") VALUES (" -> ) VALUES (
A4: End | B4: =");" -> );
A5: Columns | B5: =B10 -> Id | C5: =C10 -> PhaseId | D5: =D10 -> StrategyId
A6: All Columns | B6: =B5 -> Id | C6: =B6 & ", " & C5 -> Id, PhaseId | D6: =C6 & ", " & D5 -> Id, PhaseId, StrategyId
A7: Statement | B7: =B2 & D6 & B3 -> INSERT INTO PhaseStrategies(Id, PhaseId, StrategyId) VALUES (
I8: ="ALTER TABLE " & $B$1 & " NOCHECK CONSTRAINT ALL" -> ALTER TABLE PhaseStrategies NOCHECK CONSTRAINT ALL
B9: Table Data | I9: ="DELETE FROM " & $B$1 & ";" -> DELETE FROM PhaseStrategies;
B10: Id | C10: PhaseId | D10: StrategyId | I10: ="SET IDENTITY_INSERT " & $B$1 & " ON;" -> SET IDENTITY_INSERT PhaseStrategies ON;
B11: 1 | C11: 1 | D11: 1 | E11: =B11 -> 1 | F11: =C11 -> 1 | G11: =D11 -> 1 | H11: =_xlfn.CONCAT(E11,",",F11,",",G11) -> 1,1,1 | I11: =$B$7 & H11 & $B$4 -> INSERT INTO PhaseStrategies(Id, PhaseId, StrategyId) VALUES (1,1,1);
B12: 2 | C12: 2 | D12: 2 | E12: =B12 -> 2 | F12: =C12 -> 2 | G12: =D12 -> 2 | H12: =_xlfn.CONCAT(E12,",",F12,",",G12) -> 2,2,2 | I12: =$B$7 & H12 & $B$4 -> INSERT INTO PhaseStrategies(Id, PhaseId, StrategyId) VALUES (2,2,2);
B13: 3 | C13: 3 | D13: 3 | E13: =B13 -> 3 | F13: =C13 -> 3 | G13: =D13 -> 3 | H13: =_xlfn.CONCAT(E13,",",F13,",",G13) -> 3,3,3 | I13: =$B$7 & H13 & $B$4 -> INSERT INTO PhaseStrategies(Id, PhaseId, StrategyId) VALUES (3,3,3);
B14: 4 | C14: 4 | D14: 4 | E14: =B14 -> 4 | F14: =C14 -> 4 | G14: =D14 -> 4 | H14: =_xlfn.CONCAT(E14,",",F14,",",G14) -> 4,4,4 | I14: =$B$7 & H14 & $B$4 -> INSERT INTO PhaseStrategies(Id, PhaseId, StrategyId) VALUES (4,4,4);
I15: ="ALTER TABLE " & $B$1 & " WITH CHECK CHECK CONSTRAINT ALL" -> ALTER TABLE PhaseStrategies WITH CHECK CHECK CONSTRAINT ALL
I16: ="SET IDENTITY_INSERT " & $B$1 & " OFF;" -> SET IDENTITY_INSERT PhaseStrategies OFF;

Sheet Channel
A1: Table Name | B1: Channels
A2: Start | B2: ="INSERT INTO " & B1 & "(" -> INSERT INTO Channels(
A3: Middle | B3: =") VALUES (" -> ) VALUES (
A4: End | B4: =");" -> );
A5: Columns | B5: =B10 -> Id | C5: =C10 -> Name
A6: All Columns | B6: =B5 -> Id | C6: =B6 & ", " & C5 -> Id, Name
A7: Statement | B7: =B2 & C6 & B3 -> INSERT INTO Channels(Id, Name) VALUES (
G8: ="ALTER TABLE " & $B$1 & " NOCHECK CONSTRAINT ALL" -> ALTER TABLE Channels NOCHECK CONSTRAINT ALL
B9: Table Data | G9: ="DELETE FROM " & $B$1 & ";" -> DELETE FROM Channels;
B10: Id | C10: Name | G10: ="SET IDENTITY_INSERT " & $B$1 & " ON;" -> SET IDENTITY_INSERT Channels ON;
B11: 1 | C11: Programmatic | D11: =B11 -> 1 | E11: ="'" & C11 & "'" -> 'Programmatic' | F11: =D11 & "," & E11 -> 1,'Programmatic' | G11: =$B$7 & F11 & $B$4 -> INSERT INTO Channels(Id, Name) VALUES (1,'Programmatic');
B12: 2 | C12: YouTube | D12: =B12 -> 2 | E12: ="'" & C12 & "'" -> 'YouTube' | F12: =D12 & "," & E12 -> 2,'YouTube' | G12: =$B$7 & F12 & $B$4 -> INSERT INTO Channels(Id, Name) VALUES (2,'YouTube');
B13: 3 | C13: Facebook / Instagram | D13: =B13 -> 3 | E13: ="'" & C13 & "'" -> 'Facebook / Instagram' | F13: =D13 & "," & E13 -> 3,'Facebook / Instagram' | G13: =$B$7 & F13 & $B$4 -> INSERT INTO Channels(Id, Name) VALUES (3,'Facebook / Instagram');
B14: 4 | C14: Instagram | D14: =B14 -> 4 | E14: ="'" & C14 & "'" -> 'Instagram' | F14: =D14 & "," & E14 -> 4,'Instagram' | G14: =$B$7 & F14 & $B$4 -> INSERT INTO Channels(Id, Name) VALUES (4,'Instagram');
B15: 5 | C15: Twitter | D15: =B15 -> 5 | E15: ="'" & C15 & "'" -> 'Twitter' | F15: =D15 & "," & E15 -> 5,'Twitter' | G15: =$B$7 & F15 & $B$4 -> INSERT INTO Channels(Id, Name) VALUES (5,'Twitter');
B16: 6 | C16: VK | D16: =B16 -> 6 | E16: ="'" & C16 & "'" -> 'VK' | F16: =D16 & "," & E16 -> 6,'VK' | G16: =$B$7 & F16 & $B$4 -> INSERT INTO Channels(Id, Name) VALUES (6,'VK');
B17: 7 | C17: Reddit | D17: =B17 -> 7 | E17: ="'" & C17 & "'" -> 'Reddit' | F17: =D17 & "," & E17 -> 7,'Reddit' | G17: =$B$7 & F17 & $B$4 -> INSERT INTO Channels(Id, Name) VALUES (7,'Reddit');
B18: 8 | C18: Outbrain | D18: =B18 -> 8 | E18: ="'" & C18 & "'" -> 'Outbrain' | F18: =D18 & "," & E18 -> 8,'Outbrain' | G18: =$B$7 & F18 & $B$4 -> INSERT INTO Channels(Id, Name) VALUES (8,'Outbrain');
B19: 9 | C19: DV360 | D19: =B19 -> 9 | E19: ="'" & C19 & "'" -> 'DV360' | F19: =D19 & "," & E19 -> 9,'DV360' | G19: =$B$7 & F19 & $B$4 -> INSERT INTO Channels(Id, Name) VALUES (9,'DV360');
B20: 10 | C20: TubeMogul | D20: =B20 -> 10 | E20: ="'" & C20 & "'" -> 'TubeMogul' | F20: =D20 & "," & E20 -> 10,'TubeMogul' | G20: =$B$7 & F20 & $B$4 -> INSERT INTO Channels(Id, Name) VALUES (10,'TubeMogul');
B21: 11 | C21: GDN / YouTube | D21: =B21 -> 11 | E21: ="'" & C21 & "'" -> 'GDN / YouTube' | F21: =D21 & "," & E21 -> 11,'GDN / YouTube' | G21: =$B$7 & F21 & $B$4 -> INSERT INTO Channels(Id, Name) VALUES (11,'GDN / YouTube');
B22: 12 | C22: GDN | D22: =B22 -> 12 | E22: ="'" & C22 & "'" -> 'GDN' | F22: =D22 & "," & E22 -> 12,'GDN' | G22: =$B$7 & F22 & $B$4 -> INSERT INTO Channels(Id, Name) VALUES (12,'GDN');
... B29: 19 | C29: Google Gmail | D29: =B29 -> 19 | E29: ="'" & C29 & "'" -> 'Google Gmail' | F29: =D29 & "," & E29 -> 19,'Google Gmail' | G29: =$B$7 & F29 & $B$4 -> INSERT INTO Channels(Id, Name) VALUES (19,'Google Gmail');
G30: ="ALTER TABLE " & $B$1 & " WITH CHECK CHECK CONSTRAINT ALL" -> ALTER TABLE Channels WITH CHECK CHECK CONSTRAINT ALL
G31: ="SET IDENTITY_INSERT " & $B$1 & " OFF;" -> SET IDENTITY_INSERT Channels OFF;

Sheet PSChannels
A1: Table Name | B1: PSChannels
A2: Start | B2: ="INSERT INTO " & B1 & "(" -> INSERT INTO PSChannels(
A3: Middle | B3: =") VALUES (" -> ) VALUES (
A4: End | B4: =");" -> );
A5: Columns | B5: =B10 -> Id | C5: =C10 -> PhaseStrategyId | D5: =D10 -> ChannelId
A6: All Columns | B6: =B5 -> Id | C6: =B6 & ", " & C5 -> Id, PhaseStrategyId | D6: =C6 & ", " & D5 -> Id, PhaseStrategyId, ChannelId
A7: Statement | B7: =B2 & D6 & B3 -> INSERT INTO PSChannels(Id, PhaseStrategyId, ChannelId) VALUES (
I8: ="ALTER TABLE " & $B$1 & " NOCHECK CONSTRAINT ALL" -> ALTER TABLE PSChannels NOCHECK CONSTRAINT ALL
B9: Table Data | I9: ="DELETE FROM " & $B$1 & ";" -> DELETE FROM PSChannels;
B10: Id | C10: PhaseStrategyId | D10: ChannelId | I10: ="SET IDENTITY_INSERT " & $B$1 & " ON;" -> SET IDENTITY_INSERT PSChannels ON;
B11: 1 | C11: 1 | D11: 1 | E11: =B11 -> 1 | F11: =C11 -> 1 | G11: =D11 -> 1 | H11: =_xlfn.CONCAT(E11,",",F11,",",G11) -> 1,1,1 | I11: =$B$7 & H11 & $B$4 -> INSERT INTO PSChannels(Id, PhaseStrategyId, ChannelId) VALUES (1,1,1);
B12: 2 | C12: 2 | D12: 2 | E12: =B12 -> 2 | F12: =C12 -> 2 | G12: =D12 -> 2 | H12: =_xlfn.CONCAT(E12,",",F12,",",G12) -> 2,2,2 | I12: =$B$7 & H12 & $B$4 -> INSERT INTO PSChannels(Id, PhaseStrategyId, ChannelId) VALUES (2,2,2);
B13: 3 | C13: 3 | D13: 3 | E13: =B13 -> 3 | F13: =C13 -> 3 | G13: =D13 -> 3 | H13: =_xlfn.CONCAT(E13,",",F13,",",G13) -> 3,3,3 | I13: =$B$7 & H13 & $B$4 -> INSERT INTO PSChannels(Id, PhaseStrategyId, ChannelId) VALUES (3,3,3);
B14: 4 | C14: 4 | D14: 4 | E14: =B14 -> 4 | F14: =C14 -> 4 | G14: =D14 -> 4 | H14: =_xlfn.CONCAT(E14,",",F14,",",G14) -> 4,4,4 | I14: =$B$7 & H14 & $B$4 -> INSERT INTO PSChannels(Id, PhaseStrategyId, ChannelId) VALUES (4,4,4);
I15: ="ALTER TABLE " & $B$1 & " WITH CHECK CHECK CONSTRAINT ALL" -> ALTER TABLE PSChannels WITH CHECK CHECK CONSTRAINT ALL
I16: ="SET IDENTITY_INSERT " & $B$1 & " OFF;" -> SET IDENTITY_INSERT PSChannels OFF;

Sheet Country
A1: Table Name | B1: Countries
A2: Start | B2: ="INSERT INTO " & B1 & "(" -> INSERT INTO Countries(
A3: Middle | B3: =") VALUES (" -> ) VALUES (
A4: End | B4: =");" -> );
A5: Columns | B5: =B10 -> Id | C5: =C10 -> Code | D5: =D10 -> Name
A6: All Columns | B6: =B5 -> Id | C6: =B6 & ", " & C5 -> Id, Code | D6: =C6 & ", " & D5 -> Id, Code, Name
A7: Statement | B7: =B2 & D6 & B3 -> INSERT INTO Countries(Id, Code, Name) VALUES (
I8: ="ALTER TABLE " & $B$1 & " NOCHECK CONSTRAINT ALL" -> ALTER TABLE Countries NOCHECK CONSTRAINT ALL
B9: Table Data | I9: ="DELETE FROM " & $B$1 & ";" -> DELETE FROM Countries;
B10: Id | C10: Code | D10: Name | I10: ="SET IDENTITY_INSERT " & $B$1 & " ON;" -> SET IDENTITY_INSERT Countries ON;
B11: 1 | C11: AU | D11: Austria | E11: =B11 -> 1 | F11: ="'" & C11 & "'" -> 'AU' | G11: ="'" & D11 & "'" -> 'Austria' | H11: =E11 & "," & F11 & "," & G11 -> 1,'AU','Austria' | I11: =$B$7 & H11 & $B$4 -> INSERT INTO Countries(Id, Code, Name) VALUES (1,'AU','Austria');
B12: 2 | C12: NZ | D12: New Zealand | E12: =B12 -> 2 | F12: ="'" & C12 & "'" -> 'NZ' | G12: ="'" & D12 & "'" -> 'New Zealand' | H12: =E12 & "," & F12 & "," & G12 -> 2,'NZ','New Zealand' | I12: =$B$7 & H12 & $B$4 -> INSERT INTO Countries(Id, Code, Name) VALUES (2,'NZ','New Zealand');
B13: 3 | C13: IT | D13: Italy | E13: =B13 -> 3 | F13: ="'" & C13 & "'" -> 'IT' | G13: ="'" & D13 & "'" -> 'Italy' | H13: =E13 & "," & F13 & "," & G13 -> 3,'IT','Italy' | I13: =$B$7 & H13 & $B$4 -> INSERT INTO Countries(Id, Code, Name) VALUES (3,'IT','Italy');
B14: 4 | C14: RU | D14: Russia | E14: =B14 -> 4 | F14: ="'" & C14 & "'" -> 'RU' | G14: ="'" & D14 & "'" -> 'Russia' | H14: =E14 & "," & F14 & "," & G14 -> 4,'RU','Russia' | I14: =$B$7 & H14 & $B$4 -> INSERT INTO Countries(Id, Code, Name) VALUES (4,'RU','Russia');
I15: ="ALTER TABLE " & $B$1 & " WITH CHECK CHECK CONSTRAINT ALL" -> ALTER TABLE Countries WITH CHECK CHECK CONSTRAINT ALL
I16: ="SET IDENTITY_INSERT " & $B$1 & " OFF;" -> SET IDENTITY_INSERT Countries OFF;

Sheet PSChannelCountries
A1: Table Name | B1: PSChannelCountries
A2: Start | B2: ="INSERT INTO " & B1 & "(" -> INSERT INTO PSChannelCountries(
A3: Middle | B3: =") VALUES (" -> ) VALUES (
A4: End | B4: =");" -> );
A5: Columns | B5: =B10 -> Id | C5: =C10 -> CountryId | D5: =D10 -> PSChannelId
A6: All Columns | B6: =B5 -> Id | C6: =B6 & ", " & C5 -> Id, CountryId | D6: =C6 & ", " & D5 -> Id, CountryId, PSChannelId
A7: Statement | B7: =B2 & D6 & B3 -> INSERT INTO PSChannelCountries(Id, CountryId, PSChannelId) VALUES (
I8: ="ALTER TABLE " & $B$1 & " NOCHECK CONSTRAINT ALL" -> ALTER TABLE PSChannelCountries NOCHECK CONSTRAINT ALL
B9: Table Data | I9: ="DELETE FROM " & $B$1 & ";" -> DELETE FROM PSChannelCountries;
B10: Id | C10: CountryId | D10: PSChannelId | I10: ="SET IDENTITY_INSERT " & $B$1 & " ON;" -> SET IDENTITY_INSERT PSChannelCountries ON;
B11: 1 | C11: 1 | D11: 1 | E11: =B11 -> 1 | F11: =C11 -> 1 | G11: =D11 -> 1 | H11: =_xlfn.CONCAT(E11,",",F11,",",G11) -> 1,1,1 | I11: =$B$7 & H11 & $B$4 -> INSERT INTO PSChannelCountries(Id, CountryId, PSChannelId) VALUES (1,1,1);
B12: 2 | C12: 2 | D12: 2 | E12: =B12 -> 2 | F12: =C12 -> 2 | G12: =D12 -> 2 | H12: =_xlfn.CONCAT(E12,",",F12,",",G12) -> 2,2,2 | I12: =$B$7 & H12 & $B$4 -> INSERT INTO PSChannelCountries(Id, CountryId, PSChannelId) VALUES (2,2,2);
B13: 3 | C13: 3 | D13: 3 | E13: =B13 -> 3 | F13: =C13 -> 3 | G13: =D13 -> 3 | H13: =_xlfn.CONCAT(E13,",",F13,",",G13) -> 3,3,3 | I13: =$B$7 & H13 & $B$4 -> INSERT INTO PSChannelCountries(Id, CountryId, PSChannelId) VALUES (3,3,3);
B14: 4 | C14: 4 | D14: 4 | E14: =B14 -> 4 | F14: =C14 -> 4 | G14: =D14 -> 4 | H14: =_xlfn.CONCAT(E14,",",F14,",",G14) -> 4,4,4 | I14: =$B$7 & H14 & $B$4 -> INSERT INTO PSChannelCountries(Id, CountryId, PSChannelId) VALUES (4,4,4);
I15: ="ALTER TABLE " & $B$1 & " WITH CHECK CHECK CONSTRAINT ALL" -> ALTER TABLE PSChannelCountries WITH CHECK CHECK CONSTRAINT ALL
I16: ="SET IDENTITY_INSERT " & $B$1 & " OFF;" -> SET IDENTITY_INSERT PSChannelCountries OFF;

Sheet Ad
A1: Table Name | B1: Ads
A2: Start | B2: ="INSERT INTO " & B1 & "(" -> INSERT INTO Ads(
A3: Middle | B3: =") VALUES (" -> ) VALUES (
A4: End | B4: =");" -> );
A5: Columns | B5: =B10 -> Id | C5: =C10 -> Name | D5: =D10 -> Device | E5: =E10 -> Dimensions | F5: =F10 -> CopyRequest | G5: =G10 -> AspectRatio | H5: =H10 -> FileTypes | I5: =I10 -> FileSize | J5: =J10 -> VideoDuration
A6: All Columns | B6: =B5 -> Id | C6: =B6 & "," & C5 -> Id,Name | D6: =C6 & "," & D5 -> Id,Name,Device | E6: =D6 & "," & E5 -> Id,Name,Device,Dimensions | F6: =E6 & "," & F5 -> Id,Name,Device,Dimensions,CopyRequest | G6: =F6 & "," & G5 -> Id,Name,Device,Dimensions,CopyRequest,AspectRatio | H6: =G6 & "," & H5 -> Id,Name,Device,Dimensions,CopyRequest,AspectRatio,FileTypes | I6: =H6 & "," & I5 -> Id,Name,Device,Dimensions,CopyRequest,AspectRatio,FileTypes,FileSize | J6: =I6 & "," & J5 -> Id,Name,Device,Dimensions,CopyRequest,AspectRatio,FileTypes,FileSize,VideoDuration
A7: Statement | B7: =B2 & J6 & B3 -> INSERT INTO Ads(Id,Name,Device,Dimensions,CopyRequest,AspectRatio,FileTypes,FileSize,VideoDuration) VALUES (
U8: ="ALTER TABLE " & $B$1 & " NOCHECK CONSTRAINT ALL" -> ALTER TABLE Ads NOCHECK CONSTRAINT ALL
B9: Table Data | U9: ="DELETE FROM " & $B$1 & ";" -> DELETE FROM Ads;
B10: Id | C10: Name | D10: Device | E10: Dimensions | F10: CopyRequest | G10: AspectRatio | H10: FileTypes | I10: FileSize | J10: VideoDuration | U10: ="SET IDENTITY_INSERT " & $B$1 & " ON;" -> SET IDENTITY_INSERT Ads ON;
B11: 1 | C11: Medium Rectangle / Video Companion Banner | D11: Mobile | E11: 160x800 | F11: No | G11: 0.67291667 | H11: JPG, PNG, GIF, HTML5 | I11: 150 KB | J11: 30s or less, 3 loops max | K11: =B11 -> 1 | L11: ="'" & C11 & "'" -> 'Medium Rectangle / Video Companion Banner' | M11: ="'" & D11 & "'" -> 'Mobile' | N11: ="'" & E11 & "'" -> '160x800' | O11: ="'" & F11 & "'" -> 'No' | P11: ="'" & G11 & "'" -> '0.672916666666667' | Q11: ="'" & H11 & "'" -> 'JPG, PNG, GIF, HTML5' | R11: ="'" & I11 & "'" -> '150 KB' | S11: ="'" & J11 & "'" -> '30s or less, 3 loops max' | T11: =K11 & "," & L11 & "," & M11 & "," & N11 & "," & O11 & "," & P11 & "," & Q11 & "," & R11 & "," & S11 -> 1,'Medium Rectangle / Video Companion Banner','Mobile','160x800','No','0.672916666666667','JPG, PNG, GIF, HTML5','150 KB','30s or less, 3 loops max' | U11: =$B$7 & T11 & $B$4 -> INSERT INTO Ads(Id,Name,Device,Dimensions,CopyRequest,AspectRatio,FileTypes,FileSize,VideoDuration) VALUES (1,'Medium Rectangle / Video Companion Banner','Mobile','160x800','No','0.672916666666667','JPG, PNG, GIF, HTML5','150 KB','30s or less, 3 loops max');
B12: 2 | C12: Leaderboard / Video Companion Banner | D12: Desktop | E12: 160x801 | F12: No | G12: 0.71458333 | H12: JPG, PNG, GIF, HTML6 | I12: 151 KB | J12: 30s or less, 3 loops max | K12: =B12 -> 2 | L12: ="'" & C12 & "'" -> 'Leaderboard / Video Companion Banner' | M12: ="'" & D12 & "'" -> 'Desktop' | N12: ="'" & E12 & "'" -> '160x801' | O12: ="'" & F12 & "'" -> 'No' | P12: ="'" & G12 & "'" -> '0.714583333333333' | Q12: ="'" & H12 & "'" -> 'JPG, PNG, GIF, HTML6' | R12: ="'" & I12 & "'" -> '151 KB' | S12: ="'" & J12 & "'" -> '30s or less, 3 loops max' | T12: =K12 & "," & L12 & "," & M12 & "," & N12 & "," & O12 & "," & P12 & "," & Q12 & "," & R12 & "," & S12 -> 2,'Leaderboard / Video Companion Banner','Desktop','160x801','No','0.714583333333333','JPG, PNG, GIF, HTML6','151 KB','30s or less, 3 loops max' | U12: =$B$7 & T12 & $B$4 -> INSERT INTO Ads(Id,Name,Device,Dimensions,CopyRequest,AspectRatio,FileTypes,FileSize,VideoDuration) VALUES (2,'Leaderboard / Video Companion Banner','Desktop','160x801','No','0.714583333333333','JPG, PNG, GIF, HTML6','151 KB','30s or less, 3 loops max');
B13: 3 | C13: Wide Skyscraper | D13: Mobile | E13: 160x802 | F13: No | G13: 0.75625 | H13: JPG, PNG, GIF, HTML7 | I13: 152 KB | J13: 30s or less, 3 loops max | K13: =B13 -> 3 | L13: ="'" & C13 & "'" -> 'Wide Skyscraper' | M13: ="'" & D13 & "'" -> 'Mobile' | N13: ="'" & E13 & "'" -> '160x802' | O13: ="'" & F13 & "'" -> 'No' | P13: ="'" & G13 & "'" -> '0.75625' | Q13: ="'" & H13 & "'" -> 'JPG, PNG, GIF, HTML7' | R13: ="'" & I13 & "'" -> '152 KB' | S13: ="'" & J13 & "'" -> '30s or less, 3 loops max' | T13: =K13 & "," & L13 & "," & M13 & "," & N13 & "," & O13 & "," & P13 & "," & Q13 & "," & R13 & "," & S13 -> 3,'Wide Skyscraper','Mobile','160x802','No','0.75625','JPG, PNG, GIF, HTML7','152 KB','30s or less, 3 loops max' | U13: =$B$7 & T13 & $B$4 -> INSERT INTO Ads(Id,Name,Device,Dimensions,CopyRequest,AspectRatio,FileTypes,FileSize,VideoDuration) VALUES (3,'Wide Skyscraper','Mobile','160x802','No','0.75625','JPG, PNG, GIF, HTML7','152 KB','30s or less, 3 loops max');
B14: 4 | C14: Half Page | D14: Mobile | E14: 160x803 | F14: No | G14: 0.79791667 | H14: JPG, PNG, GIF, HTML8 | I14: 153 KB | J14: 30s or less, 3 loops max | K14: =B14 -> 4 | L14: ="'" & C14 & "'" -> 'Half Page' | M14: ="'" & D14 & "'" -> 'Mobile' | N14: ="'" & E14 & "'" -> '160x803' | O14: ="'" & F14 & "'" -> 'No' | P14: ="'" & G14 & "'" -> '0.797916666666667' | Q14: ="'" & H14 & "'" -> 'JPG, PNG, GIF, HTML8' | R14: ="'" & I14 & "'" -> '153 KB' | S14: ="'" & J14 & "'" -> '30s or less, 3 loops max' | T14: =K14 & "," & L14 & "," & M14 & "," & N14 & "," & O14 & "," & P14 & "," & Q14 & "," & R14 & "," & S14 -> 4,'Half Page','Mobile','160x803','No','0.797916666666667','JPG, PNG, GIF, HTML8','153 KB','30s or less, 3 loops max' | U14: =$B$7 & T14 & $B$4 -> INSERT INTO Ads(Id,Name,Device,Dimensions,CopyRequest,AspectRatio,FileTypes,FileSize,VideoDuration) VALUES (4,'Half Page','Mobile','160x803','No','0.797916666666667','JPG, PNG, GIF, HTML8','153 KB','30s or less, 3 loops max');
B15: 5 | C15: Billboard | D15: Desktop | E15: 160x804 | F15: No | G15: 0.83958333 | H15: JPG, PNG, GIF, HTML9 | I15: 154 KB | J15: 30s or less, 3 loops max | K15: =B15 -> 5 | L15: ="'" & C15 & "'" -> 'Billboard' | M15: ="'" & D15 & "'" -> 'Desktop' | N15: ="'" & E15 & "'" -> '160x804' | O15: ="'" & F15 & "'" -> 'No' | P15: ="'" & G15 & "'" -> '0.839583333333333' | Q15: ="'" & H15 & "'" -> 'JPG, PNG, GIF, HTML9' | R15: ="'" & I15 & "'" -> '154 KB' | S15: ="'" & J15 & "'" -> '30s or less, 3 loops max' | T15: =K15 & "," & L15 & "," & M15 & "," & N15 & "," & O15 & "," & P15 & "," & Q15 & "," & R15 & "," & S15 -> 5,'Billboard','Desktop','160x804','No','0.839583333333333','JPG, PNG, GIF, HTML9','154 KB','30s or less, 3 loops max' | U15: =$B$7 & T15 & $B$4 -> INSERT INTO Ads(Id,Name,Device,Dimensions,CopyRequest,AspectRatio,FileTypes,FileSize,VideoDuration) VALUES (5,'Billboard','Desktop','160x804','No','0.839583333333333','JPG, PNG, GIF, HTML9','154 KB','30s or less, 3 loops max');
B16: 6 | C16: Mobile Leaderboard | D16: Mobile | E16: 160x805 | F16: No | G16: 0.88125 | H16: JPG, PNG, GIF, HTML10 | I16: 155 KB | J16: 30s or less, 3 loops max | K16: =B16 -> 6 | L16: ="'" & C16 & "'" -> 'Mobile Leaderboard' | M16: ="'" & D16 & "'" -> 'Mobile' | N16: ="'" & E16 & "'" -> '160x805' | O16: ="'" & F16 & "'" -> 'No' | P16: ="'" & G16 & "'" -> '0.88125' | Q16: ="'" & H16 & "'" -> 'JPG, PNG, GIF, HTML10' | R16: ="'" & I16 & "'" -> '155 KB' | S16: ="'" & J16 & "'" -> '30s or less, 3 loops max' | T16: =K16 & "," & L16 & "," & M16 & "," & N16 & "," & O16 & "," & P16 & "," & Q16 & "," & R16 & "," & S16 -> 6,'Mobile Leaderboard','Mobile','160x805','No','0.88125','JPG, PNG, GIF, HTML10','155 KB','30s or less, 3 loops max' | U16: =$B$7 & T16 & $B$4 -> INSERT INTO Ads(Id,Name,Device,Dimensions,CopyRequest,AspectRatio,FileTypes,FileSize,VideoDuration) VALUES (6,'Mobile Leaderboard','Mobile','160x805','No','0.88125','JPG, PNG, GIF, HTML10','155 KB','30s or less, 3 loops max');
B17: 7 | C17: Mobile Banner | D17: Mobile | E17: 160x806 | F17: No | G17: 0.92291667 | H17: JPG, PNG, GIF, HTML11 | I17: 156 KB | J17: 30s or less, 3 loops max | K17: =B17 -> 7 | L17: ="'" & C17 & "'" -> 'Mobile Banner' | M17: ="'" & D17 & "'" -> 'Mobile' | N17: ="'" & E17 & "'" -> '160x806' | O17: ="'" & F17 & "'" -> 'No' | P17: ="'" & G17 & "'" -> '0.922916666666667' | Q17: ="'" & H17 & "'" -> 'JPG, PNG, GIF, HTML11' | R17: ="'" & I17 & "'" -> '156 KB' | S17: ="'" & J17 & "'" -> '30s or less, 3 loops max' | T17: =K17 & "," & L17 & "," & M17 & "," & N17 & "," & O17 & "," & P17 & "," & Q17 & "," & R17 & "," & S17 -> 7,'Mobile Banner','Mobile','160x806','No','0.922916666666667','JPG, PNG, GIF, HTML11','156 KB','30s or less, 3 loops max' | U17: =$B$7 & T17 & $B$4 -> INSERT INTO Ads(Id,Name,Device,Dimensions,CopyRequest,AspectRatio,FileTypes,FileSize,VideoDuration) VALUES (7,'Mobile Banner','Mobile','160x806','No','0.922916666666667','JPG, PNG, GIF, HTML11','156 KB','30s or less, 3 loops max');
B18: 8 | C18: Large Mobile Banner | D18: Mobile | E18: 160x807 | F18: No | G18: 0.96458333 | H18: JPG, PNG, GIF, HTML12 | I18: 157 KB | J18: 30s or less, 3 loops max | K18: =B18 -> 8 | L18: ="'" & C18 & "'" -> 'Large Mobile Banner' | M18: ="'" & D18 & "'" -> 'Mobile' | N18: ="'" & E18 & "'" -> '160x807' | O18: ="'" & F18 & "'" -> 'No' | P18: ="'" & G18 & "'" -> '0.964583333333333' | Q18: ="'" & H18 & "'" -> 'JPG, PNG, GIF, HTML12' | R18: ="'" & I18 & "'" -> '157 KB' | S18: ="'" & J18 & "'" -> '30s or less, 3 loops max' | T18: =K18 & "," & L18 & "," & M18 & "," & N18 & "," & O18 & "," & P18 & "," & Q18 & "," & R18 & "," & S18 -> 8,'Large Mobile Banner','Mobile','160x807','No','0.964583333333333','JPG, PNG, GIF, HTML12','157 KB','30s or less, 3 loops max' | U18: =$B$7 & T18 & $B$4 -> INSERT INTO Ads(Id,Name,Device,Dimensions,CopyRequest,AspectRatio,FileTypes,FileSize,VideoDuration) VALUES (8,'Large Mobile Banner','Mobile','160x807','No','0.964583333333333','JPG, PNG, GIF, HTML12','157 KB','30s or less, 3 loops max');
B19: 9 | C19: Master Landscape Video | D19: Desktop | E19: 160x808 | F19: No | G19: 0.00625 | H19: JPG, PNG, GIF, HTML13 | I19: 158 KB | J19: 30s or less, 3 loops max | K19: =B19 -> 9 | L19: ="'" & C19 & "'" -> 'Master Landscape Video' | M19: ="'" & D19 & "'" -> 'Desktop' | N19: ="'" & E19 & "'" -> '160x808' | O19: ="'" & F19 & "'" -> 'No' | P19: ="'" & G19 & "'" -> '0.00625' | Q19: ="'" & H19 & "'" -> 'JPG, PNG, GIF, HTML13' | R19: ="'" & I19 & "'" -> '158 KB' | S19: ="'" & J19 & "'" -> '30s or less, 3 loops max' | T19: =K19 & "," & L19 & "," & M19 & "," & N19 & "," & O19 & "," & P19 & "," & Q19 & "," & R19 & "," & S19 -> 9,'Master Landscape Video','Desktop','160x808','No','0.00625','JPG, PNG, GIF, HTML13','158 KB','30s or less, 3 loops max' | U19: =$B$7 & T19 & $B$4 -> INSERT INTO Ads(Id,Name,Device,Dimensions,CopyRequest,AspectRatio,FileTypes,FileSize,VideoDuration) VALUES (9,'Master Landscape Video','Desktop','160x808','No','0.00625','JPG, PNG, GIF, HTML13','158 KB','30s or less, 3 loops max');
B20: 10 | C20: Master Portrait Video | D20: Mobile | E20: 160x809 | F20: No | G20: 0.047916667 | H20: JPG, PNG, GIF, HTML14 | I20: 159 KB | J20: 30s or less, 3 loops max | K20: =B20 -> 10 | L20: ="'" & C20 & "'" -> 'Master Portrait Video' | M20: ="'" & D20 & "'" -> 'Mobile' | N20: ="'" & E20 & "'" -> '160x809' | O20: ="'" & F20 & "'" -> 'No' | P20: ="'" & G20 & "'" -> '0.0479166666666667' | Q20: ="'" & H20 & "'" -> 'JPG, PNG, GIF, HTML14' | R20: ="'" & I20 & "'" -> '159 KB' | S20: ="'" & J20 & "'" -> '30s or less, 3 loops max' | T20: =K20 & "," & L20 & "," & M20 & "," & N20 & "," & O20 & "," & P20 & "," & Q20 & "," & R20 & "," & S20 -> 10,'Master Portrait Video','Mobile','160x809','No','0.0479166666666667','JPG, PNG, GIF, HTML14','159 KB','30s or less, 3 loops max' | U20: =$B$7 & T20 & $B$4 -> INSERT INTO Ads(Id,Name,Device,Dimensions,CopyRequest,AspectRatio,FileTypes,FileSize,VideoDuration) VALUES (10,'Master Portrait Video','Mobile','160x809','No','0.0479166666666667','JPG, PNG, GIF, HTML14','159 KB','30s or less, 3 loops max');
B21: 11 | C21: Master Square Video | D21: Mobile | E21: 160x810 | F21: No | G21: 0.089583333 | H21: JPG, PNG, GIF, HTML15 | I21: 160 KB | J21: 30s or less, 3 loops max | K21: =B21 -> 11 | L21: ="'" & C21 & "'" -> 'Master Square Video' | M21: ="'" & D21 & "'" -> 'Mobile' | N21: ="'" & E21 & "'" -> '160x810' | O21: ="'" & F21 & "'" -> 'No' | P21: ="'" & G21 & "'" -> '0.0895833333333333' | Q21: ="'" & H21 & "'" -> 'JPG, PNG, GIF, HTML15' | R21: ="'" & I21 & "'" -> '160 KB' | S21: ="'" & J21 & "'" -> '30s or less, 3 loops max' | T21: =K21 & "," & L21 & "," & M21 & "," & N21 & "," & O21 & "," & P21 & "," & Q21 & "," & R21 & "," & S21 -> 11,'Master Square Video','Mobile','160x810','No','0.0895833333333333','JPG, PNG, GIF, HTML15','160 KB','30s or less, 3 loops max' | U21: =$B$7 & T21 & $B$4 -> INSERT INTO Ads(Id,Name,Device,Dimensions,CopyRequest,AspectRatio,FileTypes,FileSize,VideoDuration) VALUES (11,'Master Square Video','Mobile','160x810','No','0.0895833333333333','JPG, PNG, GIF, HTML15','160 KB','30s or less, 3 loops max');
B22: 12 | C22: Regional Ad - Russia | D22: Desktop | E22: 160x811 | F22: No | G22: 0.13125 | H22: JPG, PNG, GIF, HTML16 | I22: 161 KB | J22: 30s or less, 3 loops max | K22: =B22 -> 12 | L22: ="'" & C22 & "'" -> 'Regional Ad - Russia' | M22: ="'" & D22 & "'" -> 'Desktop' | N22: ="'" & E22 & "'" -> '160x811' | O22: ="'" & F22 & "'" -> 'No' | P22: ="'" & G22 & "'" -> '0.13125' | Q22: ="'" & H22 & "'" -> 'JPG, PNG, GIF, HTML16' | R22: ="'" & I22 & "'" -> '161 KB' | S22: ="'" & J22 & "'" -> '30s or less, 3 loops max' | T22: =K22 & "," & L22 & "," & M22 & "," & N22 & "," & O22 & "," & P22 & "," & Q22 & "," & R22 & "," & S22 -> 12,'Regional Ad - Russia','Desktop','160x811','No','0.13125','JPG, PNG, GIF, HTML16','161 KB','30s or less, 3 loops max' | U22: =$B$7 & T22 & $B$4 -> INSERT INTO Ads(Id,Name,Device,Dimensions,CopyRequest,AspectRatio,FileTypes,FileSize,VideoDuration) VALUES (12,'Regional Ad - Russia','Desktop','160x811','No','0.13125','JPG, PNG, GIF, HTML16','161 KB','30s or less, 3 loops max');
... B34: 24 | C34: Responsive Display Ad | D34: Desktop | E34: 160x823 | F34: No | G34: 0.63125 | H34: JPG, PNG, GIF, HTML28 | I34: 173 KB | J34: 30s or less, 3 loops max | K34: =B34 -> 24 | L34: ="'" & C34 & "'" -> 'Responsive Display Ad' | M34: ="'" & D34 & "'" -> 'Desktop' | N34: ="'" & E34 & "'" -> '160x823' | O34: ="'" & F34 & "'" -> 'No' | P34: ="'" & G34 & "'" -> '0.63125' | Q34: ="'" & H34 & "'" -> 'JPG, PNG, GIF, HTML28' | R34: ="'" & I34 & "'" -> '173 KB' | S34: ="'" & J34 & "'" -> '30s or less, 3 loops max' | T34: =K34 & "," & L34 & "," & M34 & "," & N34 & "," & O34 & "," & P34 & "," & Q34 & "," & R34 & "," & S34 -> 24,'Responsive Display Ad','Desktop','160x823','No','0.63125','JPG, PNG, GIF, HTML28','173 KB','30s or less, 3 loops max' | U34: =$B$7 & T34 & $B$4 -> INSERT INTO Ads(Id,Name,Device,Dimensions,CopyRequest,AspectRatio,FileTypes,FileSize,VideoDuration) VALUES (24,'Responsive Display Ad','Desktop','160x823','No','0.63125','JPG, PNG, GIF, HTML28','173 KB','30s or less, 3 loops max');
U35: ="ALTER TABLE " & $B$1 & " WITH CHECK CHECK CONSTRAINT ALL" -> ALTER TABLE Ads WITH CHECK CHECK CONSTRAINT ALL
U36: ="SET IDENTITY_INSERT " & $B$1 & " OFF;" -> SET IDENTITY_INSERT Ads OFF;

Sheet PSChannelCountriesAds
A1: Table Name | B1: PSChannelCountryAds
A2: Start | B2: ="INSERT INTO " & B1 & "(" -> INSERT INTO PSChannelCountryAds(
A3: Middle | B3: =") VALUES (" -> ) VALUES (
A4: End | B4: =");" -> );
A5: Columns | B5: =B10 -> Id | C5: =C10 -> PSChannelCountryId | D5: =D10 -> AdId
A6: All Columns | B6: =B5 -> Id | C6: =B6 & ", " & C5 -> Id, PSChannelCountryId | D6: =C6 & ", " & D5 -> Id, PSChannelCountryId, AdId
A7: Statement | B7: =B2 & D6 & B3 -> INSERT INTO PSChannelCountryAds(Id, PSChannelCountryId, AdId) VALUES (
I8: ="ALTER TABLE " & $B$1 & " NOCHECK CONSTRAINT ALL" -> ALTER TABLE PSChannelCountryAds NOCHECK CONSTRAINT ALL
B9: Table Data | I9: ="DELETE FROM " & $B$1 & ";" -> DELETE FROM PSChannelCountryAds;
B10: Id | C10: PSChannelCountryId | D10: AdId | I10: ="SET IDENTITY_INSERT " & $B$1 & " ON;" -> SET IDENTITY_INSERT PSChannelCountryAds ON;
B11: 1 | C11: 1 | D11: 1 | E11: =B11 -> 1 | F11: =C11 -> 1 | G11: =D11 -> 1 | H11: =_xlfn.CONCAT(E11,",",F11,",",G11) -> 1,1,1 | I11: =$B$7 & H11 & $B$4 -> INSERT INTO PSChannelCountryAds(Id, PSChannelCountryId, AdId) VALUES (1,1,1);
B12: 2 | C12: 2 | D12: 2 | E12: =B12 -> 2 | F12: =C12 -> 2 | G12: =D12 -> 2 | H12: =_xlfn.CONCAT(E12,",",F12,",",G12) -> 2,2,2 | I12: =$B$7 & H12 & $B$4 -> INSERT INTO PSChannelCountryAds(Id, PSChannelCountryId, AdId) VALUES (2,2,2);
B13: 3 | C13: 3 | D13: 3 | E13: =B13 -> 3 | F13: =C13 -> 3 | G13: =D13 -> 3 | H13: =_xlfn.CONCAT(E13,",",F13,",",G13) -> 3,3,3 | I13: =$B$7 & H13 & $B$4 -> INSERT INTO PSChannelCountryAds(Id, PSChannelCountryId, AdId) VALUES (3,3,3);
B14: 4 | C14: 4 | D14: 4 | E14: =B14 -> 4 | F14: =C14 -> 4 | G14: =D14 -> 4 | H14: =_xlfn.CONCAT(E14,",",F14,",",G14) -> 4,4,4 | I14: =$B$7 & H14 & $B$4 -> INSERT INTO PSChannelCountryAds(Id, PSChannelCountryId, AdId) VALUES (4,4,4);
I15: ="ALTER TABLE " & $B$1 & " WITH CHECK CHECK CONSTRAINT ALL" -> ALTER TABLE PSChannelCountryAds WITH CHECK CHECK CONSTRAINT ALL
I16: ="SET IDENTITY_INSERT " & $B$1 & " OFF;" -> SET IDENTITY_INSERT PSChannelCountryAds OFF;
